Workbook

Sheet README
A1: HealthConnect Appointment Data — Data Quality Assessment
A2: AnalystLab Africa — HealthConnect Experience Lab — Week 4 — Data Analytics Track
A5: Purpose
A6: This workbook documents the initial data quality assessment of HealthConnect_Appointment_Data (5,000 appointment records, 18 substantive fields), performed as part of the Week 4 Data Analytics track deliverable. All checks are built as live Excel formulas referencing the raw data on the 'Raw_Data' sheet, so every figure below recalculates automatically if the source data changes.
A8: How this workbook is organised
A9: • Raw_Data — the source data exactly as received, plus five helper columns (U–Y) that flag duplicates and logical inconsistencies row-by-row. Nothing in the original 20 columns (A–T) has been altered, edited, or deleted, per the project's 'do not overwrite original resources' instruction.
A10: • DQ_Assessment — the summary checks: completeness, duplicates, categorical consistency, numeric ranges/outliers, logical consistency, and outcome distribution. All values are formulas.
A11: • Findings_Summary — a short written summary of what the checks found and what it means for the next phase of analysis.
A13: Note on the two unlabeled columns
A14: The source file contained two columns with no header (columns S and T). Column S is completely blank across all 5,000 rows. Column T is blank except for a single stray numeric value (2423) in row 2, with no accompanying label or context. Both are preserved as-is on Raw_Data and flagged in the completeness and findings sections — they should not be used in analysis until their origin is confirmed against the Data Dictionary.

Sheet Raw_Data
A1: appointment_id | B1: patient_id | C1: gender | D1: age | E1: age_group | F1: appointment_type | G1: booking_date | H1: appointment_date | I1: appointment_day | J1: appointment_time | K1: booking_lead_days | L1: previous_appointments | M1: previous_no_shows | N1: reminder_sent | O1: reminder_channel | P1: distance_to_clinic_km | Q1: waiting_time_minutes | R1: appointment_outcome | S1: Extra_Column_1 (unlabeled in source) | T1: Extra_Column_2 (unlabeled in source) | U1: Dup_AppointmentID_Flag | V1: Dup_Booking_Flag (same patient+date+time) | W1: LeadDays_Check | X1: Weekday_Check | Y1: ReminderChannel_Logic_Check
A2: HC-00001 | B2: P-1613 | C2: Female | D2: 39 | E2: 35-44 | F2: Follow-up | G2: 45694 | H2: 45706 | I2: Tuesday | J2: Afternoon | K2: 12 | L2: 2 | M2: 0 | N2: Yes | O2: WhatsApp | P2: 19.3 | Q2: 29 | R2: No-Show | T2: 2423 | U2: =IF(COUNTIF($A$2:$A$5001,A2)>1,"Duplicate","Unique") -> Unique | V2: =IF(COUNTIFS($B$2:$B$5001,B2,$H$2:$H$5001,H2,$J$2:$J$5001,J2)>1,"Possible Duplicate Booking","Unique") -> Unique | W2: =IF((H2-G2)<>K2,"Mismatch","OK") -> OK | X2: =IF(TEXT(H2,"dddd")<>I2,"Mismatch","OK") -> OK | Y2: =IF(AND(N2="No",O2<>""),"Unexpected: channel present but no reminder sent",IF(AND(N2="Yes",O2=""),"Missing channel for sent reminder","OK")) -> OK
A3: HC-00002 | B3: P-0813 | C3: Male | D3: 31 | E3: 25-34 | F3: Specialist Consultation | G3: 46078 | H3: 46080 | I3: Friday | J3: Morning | K3: 2 | L3: 6 | M3: 0 | N3: Yes | O3: SMS | P3: 14.3 | Q3: 42 | R3: Attended | U3: =IF(COUNTIF($A$2:$A$5001,A3)>1,"Duplicate","Unique") -> Unique | V3: =IF(COUNTIFS($B$2:$B$5001,B3,$H$2:$H$5001,H3,$J$2:$J$5001,J3)>1,"Possible Duplicate Booking","Unique") -> Unique | W3: =IF((H3-G3)<>K3,"Mismatch","OK") -> OK | X3: =IF(TEXT(H3,"dddd")<>I3,"Mismatch","OK") -> OK | Y3: =IF(AND(N3="No",O3<>""),"Unexpected: channel present but no reminder sent",IF(AND(N3="Yes",O3=""),"Missing channel for sent reminder","OK")) -> OK
A4: HC-00003 | B4: P-1366 | C4: Female | D4: 50 | E4: 45-54 | F4: General Consultation | G4: 45977 | H4: 46015 | I4: Wednesday | J4: Morning | K4: 38 | L4: 5 | M4: 1 | N4: Yes | O4: SMS | P4: 11.4 | Q4: 11 | R4: No-Show | U4: =IF(COUNTIF($A$2:$A$5001,A4)>1,"Duplicate","Unique") -> Unique | V4: =IF(COUNTIFS($B$2:$B$5001,B4,$H$2:$H$5001,H4,$J$2:$J$5001,J4)>1,"Possible Duplicate Booking","Unique") -> Unique | W4: =IF((H4-G4)<>K4,"Mismatch","OK") -> OK | X4: =IF(TEXT(H4,"dddd")<>I4,"Mismatch","OK") -> OK | Y4: =IF(AND(N4="No",O4<>""),"Unexpected: channel present but no reminder sent",IF(AND(N4="Yes",O4=""),"Missing channel for sent reminder","OK")) -> OK
A5: HC-00004 | B5: P-1031 | C5: Male | D5: 59 | E5: 55-64 | F5: Follow-up | G5: 45856 | H5: 45897 | I5: Thursday | J5: Evening | K5: 41 | L5: 3 | M5: 1 | N5: Yes | O5: SMS | P5: 7.4 | Q5: 35 | R5: Attended | U5: =IF(COUNTIF($A$2:$A$5001,A5)>1,"Duplicate","Unique") -> Unique | V5: =IF(COUNTIFS($B$2:$B$5001,B5,$H$2:$H$5001,H5,$J$2:$J$5001,J5)>1,"Possible Duplicate Booking","Unique") -> Unique | W5: =IF((H5-G5)<>K5,"Mismatch","OK") -> OK | X5: =IF(TEXT(H5,"dddd")<>I5,"Mismatch","OK") -> OK | Y5: =IF(AND(N5="No",O5<>""),"Unexpected: channel present but no reminder sent",IF(AND(N5="Yes",O5=""),"Missing channel for sent reminder","OK")) -> OK
A6: HC-00005 | B6: P-1458 | C6: Female | D6: 34 | E6: 25-34 | F6: Follow-up | G6: 45847 | H6: 45894 | I6: Monday | J6: Afternoon | K6: 47 | L6: 3 | M6: 1 | N6: Yes | O6: Email | P6: 5.6 | Q6: 27 | R6: No-Show | U6: =IF(COUNTIF($A$2:$A$5001,A6)>1,"Duplicate","Unique") -> Unique | V6: =IF(COUNTIFS($B$2:$B$5001,B6,$H$2:$H$5001,H6,$J$2:$J$5001,J6)>1,"Possible Duplicate Booking","Unique") -> Unique | W6: =IF((H6-G6)<>K6,"Mismatch","OK") -> OK | X6: =IF(TEXT(H6,"dddd")<>I6,"Mismatch","OK") -> OK | Y6: =IF(AND(N6="No",O6<>""),"Unexpected: channel present but no reminder sent",IF(AND(N6="Yes",O6=""),"Missing channel for sent reminder","OK")) -> OK
A7: HC-00006 | B7: P-0523 | C7: Male | D7: 66 | E7: 65+ | F7: Specialist Consultation | G7: 46069 | H7: 46126 | I7: Tuesday | J7: Morning | K7: 57 | L7: 4 | M7: 2 | N7: No | P7: 3.1 | Q7: 36 | R7: No-Show | U7: =IF(COUNTIF($A$2:$A$5001,A7)>1,"Duplicate","Unique") -> Unique | V7: =IF(COUNTIFS($B$2:$B$5001,B7,$H$2:$H$5001,H7,$J$2:$J$5001,J7)>1,"Possible Duplicate Booking","Unique") -> Unique | W7: =IF((H7-G7)<>K7,"Mismatch","OK") -> OK | X7: =IF(TEXT(H7,"dddd")<>I7,"Mismatch","OK") -> OK | Y7: =IF(AND(N7="No",O7<>""),"Unexpected: channel present but no reminder sent",IF(AND(N7="Yes",O7=""),"Missing channel for sent reminder","OK")) -> OK
A8: HC-00007 | B8: P-0776 | C8: Male | D8: 58 | E8: 55-64 | F8: Diagnostic Test | G8: 45674 | H8: 45704 | I8: Sunday | J8: Afternoon | K8: 30 | L8: 4 | M8: 1 | N8: Yes | O8: WhatsApp | P8: 8.2 | Q8: 30 | R8: No-Show | U8: =IF(COUNTIF($A$2:$A$5001,A8)>1,"Duplicate","Unique") -> Unique | V8: =IF(COUNTIFS($B$2:$B$5001,B8,$H$2:$H$5001,H8,$J$2:$J$5001,J8)>1,"Possible Duplicate Booking","Unique") -> Unique | W8: =IF((H8-G8)<>K8,"Mismatch","OK") -> OK | X8: =IF(TEXT(H8,"dddd")<>I8,"Mismatch","OK") -> OK | Y8: =IF(AND(N8="No",O8<>""),"Unexpected: channel present but no reminder sent",IF(AND(N8="Yes",O8=""),"Missing channel for sent reminder","OK")) -> OK
A9: HC-00008 | B9: P-0927 | C9: Female | D9: 28 | E9: 25-34 | F9: Specialist Consultation | G9: 45988 | H9: 46038 | I9: Friday | J9: Afternoon | K9: 50 | L9: 6 | M9: 1 | N9: Yes | O9: SMS | P9: 19.2 | Q9: 21 | R9: Attended | U9: =IF(COUNTIF($A$2:$A$5001,A9)>1,"Duplicate","Unique") -> Unique | V9: =IF(COUNTIFS($B$2:$B$5001,B9,$H$2:$H$5001,H9,$J$2:$J$5001,J9)>1,"Possible Duplicate Booking","Unique") -> Unique | W9: =IF((H9-G9)<>K9,"Mismatch","OK") -> OK | X9: =IF(TEXT(H9,"dddd")<>I9,"Mismatch","OK") -> OK | Y9: =IF(AND(N9="No",O9<>""),"Unexpected: channel present but no reminder sent",IF(AND(N9="Yes",O9=""),"Missing channel for sent reminder","OK")) -> OK
A10: HC-00009 | B10: P-0388 | C10: Male | D10: 77 | E10: 65+ | F10: Follow-up | G10: 45725 | H10: 45768 | I10: Monday | J10: Afternoon | K10: 43 | L10: 3 | M10: 0 | N10: Yes | O10: SMS | P10: 10.1 | Q10: 27 | R10: No-Show | U10: =IF(COUNTIF($A$2:$A$5001,A10)>1,"Duplicate","Unique") -> Unique | V10: =IF(COUNTIFS($B$2:$B$5001,B10,$H$2:$H$5001,H10,$J$2:$J$5001,J10)>1,"Possible Duplicate Booking","Unique") -> Unique | W10: =IF((H10-G10)<>K10,"Mismatch","OK") -> OK | X10: =IF(TEXT(H10,"dddd")<>I10,"Mismatch","OK") -> OK | Y10: =IF(AND(N10="No",O10<>""),"Unexpected: channel present but no reminder sent",IF(AND(N10="Yes",O10=""),"Missing channel for sent reminder","OK")) -> OK
A11: HC-00010 | B11: P-0371 | C11: Female | D11: 20 | E11: 18-24 | F11: Follow-up | G11: 45693 | H11: 45709 | I11: Friday | J11: Afternoon | K11: 16 | L11: 2 | M11: 0 | N11: Yes | O11: SMS | P11: 28 | Q11: 20 | R11: Attended | U11: =IF(COUNTIF($A$2:$A$5001,A11)>1,"Duplicate","Unique") -> Unique | V11: =IF(COUNTIFS($B$2:$B$5001,B11,$H$2:$H$5001,H11,$J$2:$J$5001,J11)>1,"Possible Duplicate Booking","Unique") -> Unique | W11: =IF((H11-G11)<>K11,"Mismatch","OK") -> OK | X11: =IF(TEXT(H11,"dddd")<>I11,"Mismatch","OK") -> OK | Y11: =IF(AND(N11="No",O11<>""),"Unexpected: channel present but no reminder sent",IF(AND(N11="Yes",O11=""),"Missing channel for sent reminder","OK")) -> OK
A12: HC-00011 | B12: P-1070 | C12: Male | D12: 59 | E12: 55-64 | F12: Follow-up | G12: 45894 | H12: 45945 | I12: Wednesday | J12: Morning | K12: 51 | L12: 6 | M12: 1 | N12: Yes | O12: Email | P12: 12.8 | Q12: 33 | R12: No-Show | U12: =IF(COUNTIF($A$2:$A$5001,A12)>1,"Duplicate","Unique") -> Unique | V12: =IF(COUNTIFS($B$2:$B$5001,B12,$H$2:$H$5001,H12,$J$2:$J$5001,J12)>1,"Possible Duplicate Booking","Unique") -> Unique | W12: =IF((H12-G12)<>K12,"Mismatch","OK") -> OK | X12: =IF(TEXT(H12,"dddd")<>I12,"Mismatch","OK") -> OK | Y12: =IF(AND(N12="No",O12<>""),"Unexpected: channel present but no reminder sent",IF(AND(N12="Yes",O12=""),"Missing channel for sent reminder","OK")) -> OK
A13: HC-00012 | B13: P-0435 | C13: Female | D13: 45 | E13: 45-54 | F13: Follow-up | G13: 46187 | H13: 46190 | I13: Wednesday | J13: Morning | K13: 3 | L13: 6 | M13: 0 | N13: Yes | O13: Email | P13: 10.3 | Q13: 15 | R13: Cancelled | U13: =IF(COUNTIF($A$2:$A$5001,A13)>1,"Duplicate","Unique") -> Unique | V13: =IF(COUNTIFS($B$2:$B$5001,B13,$H$2:$H$5001,H13,$J$2:$J$5001,J13)>1,"Possible Duplicate Booking","Unique") -> Unique | W13: =IF((H13-G13)<>K13,"Mismatch","OK") -> OK | X13: =IF(TEXT(H13,"dddd")<>I13,"Mismatch","OK") -> OK | Y13: =IF(AND(N13="No",O13<>""),"Unexpected: channel present but no reminder sent",IF(AND(N13="Yes",O13=""),"Missing channel for sent reminder","OK")) -> OK
A14: HC-00013 | B14: P-0433 | C14: Male | D14: 59 | E14: 55-64 | F14: General Consultation | G14: 46023 | H14: 46059 | I14: Friday | J14: Morning | K14: 36 | L14: 2 | M14: 1 | N14: No | P14: 28.3 | Q14: 16 | R14: Cancelled | U14: =IF(COUNTIF($A$2:$A$5001,A14)>1,"Duplicate","Unique") -> Unique | V14: =IF(COUNTIFS($B$2:$B$5001,B14,$H$2:$H$5001,H14,$J$2:$J$5001,J14)>1,"Possible Duplicate Booking","Unique") -> Unique | W14: =IF((H14-G14)<>K14,"Mismatch","OK") -> OK | X14: =IF(TEXT(H14,"dddd")<>I14,"Mismatch","OK") -> OK | Y14: =IF(AND(N14="No",O14<>""),"Unexpected: channel present but no reminder sent",IF(AND(N14="Yes",O14=""),"Missing channel for sent reminder","OK")) -> OK
A15: HC-00014 | B15: P-0326 | C15: Female | D15: 66 | E15: 65+ | F15: Follow-up | G15: 46016 | H15: 46073 | I15: Friday | J15: Afternoon | K15: 57 | L15: 1 | M15: 0 | N15: No | P15: 5.5 | Q15: 22 | R15: Attended | U15: =IF(COUNTIF($A$2:$A$5001,A15)>1,"Duplicate","Unique") -> Unique | V15: =IF(COUNTIFS($B$2:$B$5001,B15,$H$2:$H$5001,H15,$J$2:$J$5001,J15)>1,"Possible Duplicate Booking","Unique") -> Unique | W15: =IF((H15-G15)<>K15,"Mismatch","OK") -> OK | X15: =IF(TEXT(H15,"dddd")<>I15,"Mismatch","OK") -> OK | Y15: =IF(AND(N15="No",O15<>""),"Unexpected: channel present but no reminder sent",IF(AND(N15="Yes",O15=""),"Missing channel for sent reminder","OK")) -> OK
A16: HC-00015 | B16: P-1342 | C16: Male | D16: 61 | E16: 55-64 | F16: Specialist Consultation | G16: 46009 | H16: 46049 | I16: Tuesday | J16: Afternoon | K16: 40 | L16: 3 | M16: 0 | N16: Yes | O16: SMS | P16: 6.6 | Q16: 31 | R16: Attended | U16: =IF(COUNTIF($A$2:$A$5001,A16)>1,"Duplicate","Unique") -> Unique | V16: =IF(COUNTIFS($B$2:$B$5001,B16,$H$2:$H$5001,H16,$J$2:$J$5001,J16)>1,"Possible Duplicate Booking","Unique") -> Unique | W16: =IF((H16-G16)<>K16,"Mismatch","OK") -> OK | X16: =IF(TEXT(H16,"dddd")<>I16,"Mismatch","OK") -> OK | Y16: =IF(AND(N16="No",O16<>""),"Unexpected: channel present but no reminder sent",IF(AND(N16="Yes",O16=""),"Missing channel for sent reminder","OK")) -> OK
A17: HC-00016 | B17: P-0353 | C17: Female | D17: 58 | E17: 55-64 | F17: Follow-up | G17: 46030 | H17: 46087 | I17: Friday | J17: Afternoon | K17: 57 | L17: 2 | M17: 0 | N17: Yes | O17: SMS | P17: 8.7 | Q17: 25 | R17: No-Show | U17: =IF(COUNTIF($A$2:$A$5001,A17)>1,"Duplicate","Unique") -> Unique | V17: =IF(COUNTIFS($B$2:$B$5001,B17,$H$2:$H$5001,H17,$J$2:$J$5001,J17)>1,"Possible Duplicate Booking","Unique") -> Unique | W17: =IF((H17-G17)<>K17,"Mismatch","OK") -> OK | X17: =IF(TEXT(H17,"dddd")<>I17,"Mismatch","OK") -> OK | Y17: =IF(AND(N17="No",O17<>""),"Unexpected: channel present but no reminder sent",IF(AND(N17="Yes",O17=""),"Missing channel for sent reminder","OK")) -> OK
A18: HC-00017 | B18: P-0930 | C18: Male | D18: 70 | E18: 65+ | F18: Specialist Consultation | G18: 45935 | H18: 45938 | I18: Wednesday | J18: Afternoon | K18: 3 | L18: 4 | M18: 3 | N18: No | P18: 13.8 | Q18: 20 | R18: Attended | U18: =IF(COUNTIF($A$2:$A$5001,A18)>1,"Duplicate","Unique") -> Unique | V18: =IF(COUNTIFS($B$2:$B$5001,B18,$H$2:$H$5001,H18,$J$2:$J$5001,J18)>1,"Possible Duplicate Booking","Unique") -> Unique | W18: =IF((H18-G18)<>K18,"Mismatch","OK") -> OK | X18: =IF(TEXT(H18,"dddd")<>I18,"Mismatch","OK") -> OK | Y18: =IF(AND(N18="No",O18<>""),"Unexpected: channel present but no reminder sent",IF(AND(N18="Yes",O18=""),"Missing channel for sent reminder","OK")) -> OK
A19: HC-00018 | B19: P-0859 | C19: Female | D19: 62 | E19: 55-64 | F19: Follow-up | G19: 45695 | H19: 45727 | I19: Tuesday | J19: Morning | K19: 32 | L19: 1 | M19: 0 | N19: Yes | O19: SMS | P19: 14 | Q19: 36 | R19: Attended | U19: =IF(COUNTIF($A$2:$A$5001,A19)>1,"Duplicate","Unique") -> Unique | V19: =IF(COUNTIFS($B$2:$B$5001,B19,$H$2:$H$5001,H19,$J$2:$J$5001,J19)>1,"Possible Duplicate Booking","Unique") -> Unique | W19: =IF((H19-G19)<>K19,"Mismatch","OK") -> OK | X19: =IF(TEXT(H19,"dddd")<>I19,"Mismatch","OK") -> OK | Y19: =IF(AND(N19="No",O19<>""),"Unexpected: channel present but no reminder sent",IF(AND(N19="Yes",O19=""),"Missing channel for sent reminder","OK")) -> OK
A20: HC-00019 | B20: P-0231 | C20: Female | D20: 69 | E20: 65+ | F20: General Consultation | G20: 46069 | H20: 46116 | I20: Saturday | J20: Morning | K20: 47 | L20: 3 | M20: 1 | N20: Yes | O20: WhatsApp | P20: 5.1 | Q20: 30 | R20: Attended | U20: =IF(COUNTIF($A$2:$A$5001,A20)>1,"Duplicate","Unique") -> Unique | V20: =IF(COUNTIFS($B$2:$B$5001,B20,$H$2:$H$5001,H20,$J$2:$J$5001,J20)>1,"Possible Duplicate Booking","Unique") -> Unique | W20: =IF((H20-G20)<>K20,"Mismatch","OK") -> OK | X20: =IF(TEXT(H20,"dddd")<>I20,"Mismatch","OK") -> OK | Y20: =IF(AND(N20="No",O20<>""),"Unexpected: channel present but no reminder sent",IF(AND(N20="Yes",O20=""),"Missing channel for sent reminder","OK")) -> OK
A21: HC-00020 | B21: P-0106 | C21: Male | D21: 43 | E21: 35-44 | F21: General Consultation | G21: 45864 | H21: 45903 | I21: Wednesday | J21: Morning | K21: 39 | L21: 4 | M21: 0 | N21: Yes | O21: WhatsApp | P21: 9.4 | Q21: 19 | R21: No-Show | U21: =IF(COUNTIF($A$2:$A$5001,A21)>1,"Duplicate","Unique") -> Unique | V21: =IF(COUNTIFS($B$2:$B$5001,B21,$H$2:$H$5001,H21,$J$2:$J$5001,J21)>1,"Possible Duplicate Booking","Unique") -> Unique | W21: =IF((H21-G21)<>K21,"Mismatch","OK") -> OK | X21: =IF(TEXT(H21,"dddd")<>I21,"Mismatch","OK") -> OK | Y21: =IF(AND(N21="No",O21<>""),"Unexpected: channel present but no reminder sent",IF(AND(N21="Yes",O21=""),"Missing channel for sent reminder","OK")) -> OK
A22: HC-00021 | B22: P-1330 | C22: Female | D22: 30 | E22: 25-34 | F22: General Consultation | G22: 45878 | H22: 45931 | I22: Wednesday | J22: Morning | K22: 53 | L22: 1 | M22: 0 | N22: Yes | O22: WhatsApp | P22: 19.9 | Q22: 13 | R22: Attended | U22: =IF(COUNTIF($A$2:$A$5001,A22)>1,"Duplicate","Unique") -> Unique | V22: =IF(COUNTIFS($B$2:$B$5001,B22,$H$2:$H$5001,H22,$J$2:$J$5001,J22)>1,"Possible Duplicate Booking","Unique") -> Unique | W22: =IF((H22-G22)<>K22,"Mismatch","OK") -> OK | X22: =IF(TEXT(H22,"dddd")<>I22,"Mismatch","OK") -> OK | Y22: =IF(AND(N22="No",O22<>""),"Unexpected: channel present but no reminder sent",IF(AND(N22="Yes",O22=""),"Missing channel for sent reminder","OK")) -> OK
A23: HC-00022 | B23: P-0597 | C23: Female | D23: 32 | E23: 25-34 | F23: General Consultation | G23: 45832 | H23: 45860 | I23: Tuesday | J23: Afternoon | K23: 28 | L23: 0 | M23: 0 | N23: No | P23: 2.9 | Q23: 22 | R23: Attended | U23: =IF(COUNTIF($A$2:$A$5001,A23)>1,"Duplicate","Unique") -> Unique | V23: =IF(COUNTIFS($B$2:$B$5001,B23,$H$2:$H$5001,H23,$J$2:$J$5001,J23)>1,"Possible Duplicate Booking","Unique") -> Unique | W23: =IF((H23-G23)<>K23,"Mismatch","OK") -> OK | X23: =IF(TEXT(H23,"dddd")<>I23,"Mismatch","OK") -> OK | Y23: =IF(AND(N23="No",O23<>""),"Unexpected: channel present but no reminder sent",IF(AND(N23="Yes",O23=""),"Missing channel for sent reminder","OK")) -> OK
A24: HC-00023 | B24: P-1623 | C24: Male | D24: 56 | E24: 55-64 | F24: Follow-up | G24: 45716 | H24: 45757 | I24: Thursday | J24: Evening | K24: 41 | L24: 2 | M24: 0 | N24: No | P24: 19.7 | Q24: 17 | R24: No-Show | U24: =IF(COUNTIF($A$2:$A$5001,A24)>1,"Duplicate","Unique") -> Unique | V24: =IF(COUNTIFS($B$2:$B$5001,B24,$H$2:$H$5001,H24,$J$2:$J$5001,J24)>1,"Possible Duplicate Booking","Unique") -> Unique | W24: =IF((H24-G24)<>K24,"Mismatch","OK") -> OK | X24: =IF(TEXT(H24,"dddd")<>I24,"Mismatch","OK") -> OK | Y24: =IF(AND(N24="No",O24<>""),"Unexpected: channel present but no reminder sent",IF(AND(N24="Yes",O24=""),"Missing channel for sent reminder","OK")) -> OK
A25: HC-00024 | B25: P-0863 | C25: Female | D25: 51 | E25: 45-54 | F25: General Consultation | G25: 46139 | H25: 46164 | I25: Friday | J25: Morning | K25: 25 | L25: 0 | M25: 0 | N25: No | P25: 11.2 | Q25: 16 | R25: Attended | U25: =IF(COUNTIF($A$2:$A$5001,A25)>1,"Duplicate","Unique") -> Unique | V25: =IF(COUNTIFS($B$2:$B$5001,B25,$H$2:$H$5001,H25,$J$2:$J$5001,J25)>1,"Possible Duplicate Booking","Unique") -> Unique | W25: =IF((H25-G25)<>K25,"Mismatch","OK") -> OK | X25: =IF(TEXT(H25,"dddd")<>I25,"Mismatch","OK") -> OK | Y25: =IF(AND(N25="No",O25<>""),"Unexpected: channel present but no reminder sent",IF(AND(N25="Yes",O25=""),"Missing channel for sent reminder","OK")) -> OK
A26: HC-00025 | B26: P-0623 | C26: Male | D26: 22 | E26: 18-24 | F26: General Consultation | G26: 46031 | H26: 46084 | I26: Tuesday | J26: Afternoon | K26: 53 | L26: 6 | M26: 1 | N26: No | P26: 11.1 | Q26: 32 | R26: Attended | U26: =IF(COUNTIF($A$2:$A$5001,A26)>1,"Duplicate","Unique") -> Unique | V26: =IF(COUNTIFS($B$2:$B$5001,B26,$H$2:$H$5001,H26,$J$2:$J$5001,J26)>1,"Possible Duplicate Booking","Unique") -> Unique | W26: =IF((H26-G26)<>K26,"Mismatch","OK") -> OK | X26: =IF(TEXT(H26,"dddd")<>I26,"Mismatch","OK") -> OK | Y26: =IF(AND(N26="No",O26<>""),"Unexpected: channel present but no reminder sent",IF(AND(N26="Yes",O26=""),"Missing channel for sent reminder","OK")) -> OK
A27: HC-00026 | B27: P-0270 | C27: Female | D27: 30 | E27: 25-34 | F27: General Consultation | G27: 46002 | H27: 46009 | I27: Thursday | J27: Morning | K27: 7 | L27: 2 | M27: 0 | N27: No | P27: 5.7 | Q27: 36 | R27: No-Show | U27: =IF(COUNTIF($A$2:$A$5001,A27)>1,"Duplicate","Unique") -> Unique | V27: =IF(COUNTIFS($B$2:$B$5001,B27,$H$2:$H$5001,H27,$J$2:$J$5001,J27)>1,"Possible Duplicate Booking","Unique") -> Unique | W27: =IF((H27-G27)<>K27,"Mismatch","OK") -> OK | X27: =IF(TEXT(H27,"dddd")<>I27,"Mismatch","OK") -> OK | Y27: =IF(AND(N27="No",O27<>""),"Unexpected: channel present but no reminder sent",IF(AND(N27="Yes",O27=""),"Missing channel for sent reminder","OK")) -> OK
A28: HC-00027 | B28: P-0224 | C28: Male | D28: 78 | E28: 65+ | F28: Specialist Consultation | G28: 45862 | H28: 45877 | I28: Friday | J28: Afternoon | K28: 15 | L28: 4 | M28: 0 | N28: Yes | O28: SMS | P28: 13.3 | Q28: 23 | R28: Attended | U28: =IF(COUNTIF($A$2:$A$5001,A28)>1,"Duplicate","Unique") -> Unique | V28: =IF(COUNTIFS($B$2:$B$5001,B28,$H$2:$H$5001,H28,$J$2:$J$5001,J28)>1,"Possible Duplicate Booking","Unique") -> Unique | W28: =IF((H28-G28)<>K28,"Mismatch","OK") -> OK | X28: =IF(TEXT(H28,"dddd")<>I28,"Mismatch","OK") -> OK | Y28: =IF(AND(N28="No",O28<>""),"Unexpected: channel present but no reminder sent",IF(AND(N28="Yes",O28=""),"Missing channel for sent reminder","OK")) -> OK
A29: HC-00028 | B29: P-0640 | C29: Male | D29: 63 | E29: 55-64 | F29: Specialist Consultation | G29: 46102 | H29: 46107 | I29: Thursday | J29: Morning | K29: 5 | L29: 5 | M29: 0 | N29: Yes | O29: WhatsApp | P29: 5.3 | Q29: 24 | R29: Attended | U29: =IF(COUNTIF($A$2:$A$5001,A29)>1,"Duplicate","Unique") -> Unique | V29: =IF(COUNTIFS($B$2:$B$5001,B29,$H$2:$H$5001,H29,$J$2:$J$5001,J29)>1,"Possible Duplicate Booking","Unique") -> Unique | W29: =IF((H29-G29)<>K29,"Mismatch","OK") -> OK | X29: =IF(TEXT(H29,"dddd")<>I29,"Mismatch","OK") -> OK | Y29: =IF(AND(N29="No",O29<>""),"Unexpected: channel present but no reminder sent",IF(AND(N29="Yes",O29=""),"Missing channel for sent reminder","OK")) -> OK
A30: HC-00029 | B30: P-0415 | C30: Female | D30: 65 | E30: 65+ | F30: General Consultation | G30: 45913 | H30: 45955 | I30: Saturday | J30: Afternoon | K30: 42 | L30: 0 | M30: 0 | N30: Yes | O30: WhatsApp | P30: 4.1 | Q30: 16 | R30: Cancelled | U30: =IF(COUNTIF($A$2:$A$5001,A30)>1,"Duplicate","Unique") -> Unique | V30: =IF(COUNTIFS($B$2:$B$5001,B30,$H$2:$H$5001,H30,$J$2:$J$5001,J30)>1,"Possible Duplicate Booking","Unique") -> Unique | W30: =IF((H30-G30)<>K30,"Mismatch","OK") -> OK | X30: =IF(TEXT(H30,"dddd")<>I30,"Mismatch","OK") -> OK | Y30: =IF(AND(N30="No",O30<>""),"Unexpected: channel present but no reminder sent",IF(AND(N30="Yes",O30=""),"Missing channel for sent reminder","OK")) -> OK
A31: HC-00030 | B31: P-0983 | C31: Female | D31: 30 | E31: 25-34 | F31: General Consultation | G31: 45886 | H31: 45900 | I31: Sunday | J31: Morning | K31: 14 | L31: 2 | M31: 1 | N31: No | P31: 5 | Q31: 12 | R31: No-Show | U31: =IF(COUNTIF($A$2:$A$5001,A31)>1,"Duplicate","Unique") -> Unique | V31: =IF(COUNTIFS($B$2:$B$5001,B31,$H$2:$H$5001,H31,$J$2:$J$5001,J31)>1,"Possible Duplicate Booking","Unique") -> Unique | W31: =IF((H31-G31)<>K31,"Mismatch","OK") -> OK | X31: =IF(TEXT(H31,"dddd")<>I31,"Mismatch","OK") -> OK | Y31: =IF(AND(N31="No",O31<>""),"Unexpected: channel present but no reminder sent",IF(AND(N31="Yes",O31=""),"Missing channel for sent reminder","OK")) -> OK
A32: HC-00031 | B32: P-0020 | C32: Male | D32: 22 | E32: 18-24 | F32: General Consultation | G32: 45884 | H32: 45903 | I32: Wednesday | J32: Morning | K32: 19 | L32: 1 | M32: 0 | N32: Yes | O32: SMS | P32: 8.9 | Q32: 33 | R32: Attended | U32: =IF(COUNTIF($A$2:$A$5001,A32)>1,"Duplicate","Unique") -> Unique | V32: =IF(COUNTIFS($B$2:$B$5001,B32,$H$2:$H$5001,H32,$J$2:$J$5001,J32)>1,"Possible Duplicate Booking","Unique") -> Unique | W32: =IF((H32-G32)<>K32,"Mismatch","OK") -> OK | X32: =IF(TEXT(H32,"dddd")<>I32,"Mismatch","OK") -> OK | Y32: =IF(AND(N32="No",O32<>""),"Unexpected: channel present but no reminder sent",IF(AND(N32="Yes",O32=""),"Missing channel for sent reminder","OK")) -> OK
A33: HC-00032 | B33: P-1631 | C33: Male | D33: 36 | E33: 35-44 | F33: General Consultation | G33: 45731 | H33: 45782 | I33: Monday | J33: Afternoon | K33: 51 | L33: 1 | M33: 0 | N33: Yes | O33: SMS | P33: 9.3 | Q33: 10 | R33: Cancelled | U33: =IF(COUNTIF($A$2:$A$5001,A33)>1,"Duplicate","Unique") -> Unique | V33: =IF(COUNTIFS($B$2:$B$5001,B33,$H$2:$H$5001,H33,$J$2:$J$5001,J33)>1,"Possible Duplicate Booking","Unique") -> Unique | W33: =IF((H33-G33)<>K33,"Mismatch","OK") -> OK | X33: =IF(TEXT(H33,"dddd")<>I33,"Mismatch","OK") -> OK | Y33: =IF(AND(N33="No",O33<>""),"Unexpected: channel present but no reminder sent",IF(AND(N33="Yes",O33=""),"Missing channel for sent reminder","OK")) -> OK
A34: HC-00033 | B34: P-0816 | C34: Female | D34: 71 | E34: 65+ | F34: General Consultation | G34: 45687 | H34: 45708 | I34: Thursday | J34: Morning | K34: 21 | L34: 3 | M34: 1 | N34: Yes | O34: SMS | P34: 11.5 | Q34: 17 | R34: Attended | U34: =IF(COUNTIF($A$2:$A$5001,A34)>1,"Duplicate","Unique") -> Unique | V34: =IF(COUNTIFS($B$2:$B$5001,B34,$H$2:$H$5001,H34,$J$2:$J$5001,J34)>1,"Possible Duplicate Booking","Unique") -> Unique | W34: =IF((H34-G34)<>K34,"Mismatch","OK") -> OK | X34: =IF(TEXT(H34,"dddd")<>I34,"Mismatch","OK") -> OK | Y34: =IF(AND(N34="No",O34<>""),"Unexpected: channel present but no reminder sent",IF(AND(N34="Yes",O34=""),"Missing channel for sent reminder","OK")) -> OK
A35: HC-00034 | B35: P-0581 | C35: Female | D35: 49 | E35: 45-54 | F35: General Consultation | G35: 45952 | H35: 45960 | I35: Thursday | J35: Afternoon | K35: 8 | L35: 3 | M35: 0 | N35: Yes | O35: Email | P35: 8.2 | Q35: 17 | R35: No-Show | U35: =IF(COUNTIF($A$2:$A$5001,A35)>1,"Duplicate","Unique") -> Unique | V35: =IF(COUNTIFS($B$2:$B$5001,B35,$H$2:$H$5001,H35,$J$2:$J$5001,J35)>1,"Possible Duplicate Booking","Unique") -> Unique | W35: =IF((H35-G35)<>K35,"Mismatch","OK") -> OK | X35: =IF(TEXT(H35,"dddd")<>I35,"Mismatch","OK") -> OK | Y35: =IF(AND(N35="No",O35<>""),"Unexpected: channel present but no reminder sent",IF(AND(N35="Yes",O35=""),"Missing channel for sent reminder","OK")) -> OK
A36: HC-00035 | B36: P-0074 | C36: Female | D36: 67 | E36: 65+ | F36: General Consultation | G36: 46141 | H36: 46142 | I36: Thursday | J36: Morning | K36: 1 | L36: 2 | M36: 0 | N36: Yes | O36: SMS | P36: 7.5 | Q36: 29 | R36: Attended | U36: =IF(COUNTIF($A$2:$A$5001,A36)>1,"Duplicate","Unique") -> Unique | V36: =IF(COUNTIFS($B$2:$B$5001,B36,$H$2:$H$5001,H36,$J$2:$J$5001,J36)>1,"Possible Duplicate Booking","Unique") -> Unique | W36: =IF((H36-G36)<>K36,"Mismatch","OK") -> OK | X36: =IF(TEXT(H36,"dddd")<>I36,"Mismatch","OK") -> OK | Y36: =IF(AND(N36="No",O36<>""),"Unexpected: channel present but no reminder sent",IF(AND(N36="Yes",O36=""),"Missing channel for sent reminder","OK")) -> OK
A37: HC-00036 | B37: P-0010 | C37: Male | D37: 48 | E37: 45-54 | F37: Diagnostic Test | G37: 45679 | H37: 45692 | I37: Tuesday | J37: Evening | K37: 13 | L37: 4 | M37: 1 | N37: Yes | O37: SMS | P37: 1.5 | Q37: 22 | R37: Attended | U37: =IF(COUNTIF($A$2:$A$5001,A37)>1,"Duplicate","Unique") -> Unique | V37: =IF(COUNTIFS($B$2:$B$5001,B37,$H$2:$H$5001,H37,$J$2:$J$5001,J37)>1,"Possible Duplicate Booking","Unique") -> Unique | W37: =IF((H37-G37)<>K37,"Mismatch","OK") -> OK | X37: =IF(TEXT(H37,"dddd")<>I37,"Mismatch","OK") -> OK | Y37: =IF(AND(N37="No",O37<>""),"Unexpected: channel present but no reminder sent",IF(AND(N37="Yes",O37=""),"Missing channel for sent reminder","OK")) -> OK
A38: HC-00037 | B38: P-0343 | C38: Male | D38: 48 | E38: 45-54 | F38: Follow-up | G38: 46071 | H38: 46126 | I38: Tuesday | J38: Morning | K38: 55 | L38: 5 | M38: 2 | N38: Yes | O38: SMS | P38: 22.6 | Q38: 18 | R38: No-Show | U38: =IF(COUNTIF($A$2:$A$5001,A38)>1,"Duplicate","Unique") -> Unique | V38: =IF(COUNTIFS($B$2:$B$5001,B38,$H$2:$H$5001,H38,$J$2:$J$5001,J38)>1,"Possible Duplicate Booking","Unique") -> Unique | W38: =IF((H38-G38)<>K38,"Mismatch","OK") -> OK | X38: =IF(TEXT(H38,"dddd")<>I38,"Mismatch","OK") -> OK | Y38: =IF(AND(N38="No",O38<>""),"Unexpected: channel present but no reminder sent",IF(AND(N38="Yes",O38=""),"Missing channel for sent reminder","OK")) -> OK
A39: HC-00038 | B39: P-1214 | C39: Female | D39: 55 | E39: 55-64 | F39: Specialist Consultation | G39: 46076 | H39: 46109 | I39: Saturday | J39: Afternoon | K39: 33 | L39: 1 | M39: 1 | N39: Yes | O39: SMS | P39: 7.1 | Q39: 39 | R39: Cancelled | U39: =IF(COUNTIF($A$2:$A$5001,A39)>1,"Duplicate","Unique") -> Unique | V39: =IF(COUNTIFS($B$2:$B$5001,B39,$H$2:$H$5001,H39,$J$2:$J$5001,J39)>1,"Possible Duplicate Booking","Unique") -> Possible Duplicate Booking | W39: =IF((H39-G39)<>K39,"Mismatch","OK") -> OK | X39: =IF(TEXT(H39,"dddd")<>I39,"Mismatch","OK") -> OK | Y39: =IF(AND(N39="No",O39<>""),"Unexpected: channel present but no reminder sent",IF(AND(N39="Yes",O39=""),"Missing channel for sent reminder","OK")) -> OK
A40: HC-00039 | B40: P-0072 | C40: Male | D40: 78 | E40: 65+ | F40: General Consultation | G40: 45749 | H40: 45809 | I40: Sunday | J40: Afternoon | K40: 60 | L40: 6 | M40: 1 | N40: Yes | O40: SMS | Q40: 42 | R40: Cancelled | U40: =IF(COUNTIF($A$2:$A$5001,A40)>1,"Duplicate","Unique") -> Unique | V40: =IF(COUNTIFS($B$2:$B$5001,B40,$H$2:$H$5001,H40,$J$2:$J$5001,J40)>1,"Possible Duplicate Booking","Unique") -> Unique | W40: =IF((H40-G40)<>K40,"Mismatch","OK") -> OK | X40: =IF(TEXT(H40,"dddd")<>I40,"Mismatch","OK") -> OK | Y40: =IF(AND(N40="No",O40<>""),"Unexpected: channel present but no reminder sent",IF(AND(N40="Yes",O40=""),"Missing channel for sent reminder","OK")) -> OK
...

Sheet DQ_Assessment
A1: HealthConnect Appointment Data — Data Quality Assessment
A2: All figures below are live formulas referencing the Raw_Data sheet.
A4: Total records (Raw_Data rows) | B4: =ROWS(Raw_Data!A2:A5001) -> 5000
A6: A. Completeness Check
A7: Column Name | B7: Excel Column | C7: Non-Blank Count | D7: Missing Count | E7: % Missing | F7: Note
A8: appointment_id | B8: A | C8: =COUNTA(Raw_Data!A2:A5001) -> 5000 | D8: =$B$4-C8 -> 0 | E8: =D8/$B$4 -> 0 | F8: Primary key — expected 0 missing
A9: patient_id | B9: B | C9: =COUNTA(Raw_Data!B2:B5001) -> 5000 | D9: =$B$4-C9 -> 0 | E9: =D9/$B$4 -> 0 | F9: Expected 0 missing
A10: gender | B10: C | C10: =COUNTA(Raw_Data!C2:C5001) -> 5000 | D10: =$B$4-C10 -> 0 | E10: =D10/$B$4 -> 0 | F10: Includes 'Prefer not to say' as a valid category
A11: age | B11: D | C11: =COUNTA(Raw_Data!D2:D5001) -> 5000 | D11: =$B$4-C11 -> 0 | E11: =D11/$B$4 -> 0
A12: age_group | B12: E | C12: =COUNTA(Raw_Data!E2:E5001) -> 5000 | D12: =$B$4-C12 -> 0 | E12: =D12/$B$4 -> 0 | F12: Derived from age — cross-check consistency later
A13: appointment_type | B13: F | C13: =COUNTA(Raw_Data!F2:F5001) -> 5000 | D13: =$B$4-C13 -> 0 | E13: =D13/$B$4 -> 0
A14: booking_date | B14: G | C14: =COUNTA(Raw_Data!G2:G5001) -> 5000 | D14: =$B$4-C14 -> 0 | E14: =D14/$B$4 -> 0
A15: appointment_date | B15: H | C15: =COUNTA(Raw_Data!H2:H5001) -> 5000 | D15: =$B$4-C15 -> 0 | E15: =D15/$B$4 -> 0
A16: appointment_day | B16: I | C16: =COUNTA(Raw_Data!I2:I5001) -> 5000 | D16: =$B$4-C16 -> 0 | E16: =D16/$B$4 -> 0 | F16: Derived from appointment_date
A17: appointment_time | B17: J | C17: =COUNTA(Raw_Data!J2:J5001) -> 5000 | D17: =$B$4-C17 -> 0 | E17: =D17/$B$4 -> 0
A18: booking_lead_days | B18: K | C18: =COUNTA(Raw_Data!K2:K5001) -> 5000 | D18: =$B$4-C18 -> 0 | E18: =D18/$B$4 -> 0
A19: previous_appointments | B19: L | C19: =COUNTA(Raw_Data!L2:L5001) -> 5000 | D19: =$B$4-C19 -> 0 | E19: =D19/$B$4 -> 0
A20: previous_no_shows | B20: M | C20: =COUNTA(Raw_Data!M2:M5001) -> 5000 | D20: =$B$4-C20 -> 0 | E20: =D20/$B$4 -> 0
A21: reminder_sent | B21: N | C21: =COUNTA(Raw_Data!N2:N5001) -> 5000 | D21: =$B$4-C21 -> 0 | E21: =D21/$B$4 -> 0
A22: reminder_channel | B22: O | C22: =COUNTA(Raw_Data!O2:O5001) -> 3634 | D22: =$B$4-C22 -> 1366 | E22: =D22/$B$4 -> 0.2732 | F22: Expected to be blank when reminder_sent = No — see Section E
A23: distance_to_clinic_km | B23: P | C23: =COUNTA(Raw_Data!P2:P5001) -> 4910 | D23: =$B$4-C23 -> 90 | E23: =D23/$B$4 -> 0.018 | F23: Missing values likely unrecorded distance — investigate before use in KPIs
A24: waiting_time_minutes | B24: Q | C24: =COUNTA(Raw_Data!Q2:Q5001) -> 4940 | D24: =$B$4-C24 -> 60 | E24: =D24/$B$4 -> 0.012 | F24: Missing values likely unrecorded on day of visit
A25: appointment_outcome | B25: R | C25: =COUNTA(Raw_Data!R2:R5001) -> 5000 | D25: =$B$4-C25 -> 0 | E25: =D25/$B$4 -> 0 | F25: Target field for no-show analysis — expected 0 missing
A26: Extra_Column_1 (unlabeled in source) | B26: S | C26: =COUNTA(Raw_Data!S2:S5001) -> 0 | D26: =$B$4-C26 -> 5000 | E26: =D26/$B$4 -> 1 | F26: Unlabeled column, fully blank — recommend dropping/confirming with data owner
A27: Extra_Column_2 (unlabeled in source) | B27: T | C27: =COUNTA(Raw_Data!T2:T5001) -> 1 | D27: =$B$4-C27 -> 4999 | E27: =D27/$B$4 -> 0.9998 | F27: Unlabeled column, one stray value with no context — investigate before use
A30: B. Duplicate Checks
A31: Check | B31: Count | C31: % of Total | D31: Note
A32: Duplicate Appointment IDs | B32: =COUNTIF(Raw_Data!U2:U5001,"Duplicate") -> 0 | C32: =B32/$B$4 -> 0 | D32: appointment_id is the primary key; any count above 0 needs investigation.
A33: Possible Duplicate Bookings (same patient, date & time slot) | B33: =COUNTIF(Raw_Data!V2:V5001,"Possible Duplicate Booking") -> 18 | C33: =B33/$B$4 -> 0.0036 | D33: Flags cases where the same patient appears booked twice in the identical slot.
A35: C. Categorical Value Consistency & Distribution
A36: gender
A37: Value | B37: Count | C37: % of Total
A38: Female | B38: =COUNTIF(Raw_Data!C2:C5001,"Female") -> 2488 | C38: =B38/$B$4 -> 0.4976
A39: Male | B39: =COUNTIF(Raw_Data!C2:C5001,"Male") -> 2404 | C39: =B39/$B$4 -> 0.4808
A40: Prefer not to say | B40: =COUNTIF(Raw_Data!C2:C5001,"Prefer not to say") -> 108 | C40: =B40/$B$4 -> 0.0216
A42: age_group
A43: Value | B43: Count | C43: % of Total
A44: 18-24 | B44: =COUNTIF(Raw_Data!E2:E5001,"18-24") -> 564 | C44: =B44/$B$4 -> 0.1128
A45: 25-34 | B45: =COUNTIF(Raw_Data!E2:E5001,"25-34") -> 783 | C45: =B45/$B$4 -> 0.1566
A46: 35-44 | B46: =COUNTIF(Raw_Data!E2:E5001,"35-44") -> 819 | C46: =B46/$B$4 -> 0.1638
...

Sheet Findings_Summary
A1: Data Quality Assessment — Findings Summary
A2: HealthConnect_Appointment_Data — 5,000 records, 18 substantive fields
A4: Overall
A5: The dataset is largely clean and internally consistent. Appointment IDs are unique with no duplicates, booking_lead_days correctly matches the date difference in every row, and appointment_day matches the true weekday of appointment_date in every row. No negative or impossible numeric values were found (age, distance, waiting time, and counts are all within plausible ranges).
A6: Missing data
A7: Three fields have missing values: reminder_channel (1,366 blanks, ~27.3%), distance_to_clinic_km (90 blanks, ~1.8%), and waiting_time_minutes (60 blanks, ~1.2%). The reminder_channel blanks are logically explained — they occur exactly where reminder_sent = 'No', so this is not really an error. Distance and waiting time gaps are smaller and appear to be genuinely unrecorded values; these fields should be handled carefully (e.g. flagged rather than imputed with an assumed value) if used directly in KPIs.
A8: Unlabeled columns
A9: The source file contains two columns with no header. One is completely empty; the other holds a single unexplained numeric value (2423) with no context. Both have been preserved unedited on Raw_Data and should be confirmed with the data owner or Data Dictionary before Week 5 — they are not used in any of the checks or proposed KPIs at this stage.
A10: Duplicates
A11: No duplicate appointment IDs and no cases of the same patient booked into the same date and time slot more than once were found.
A12: Categorical fields
A13: All categorical fields (gender, age_group, appointment_type, appointment_day, appointment_time, reminder_sent, reminder_channel, appointment_outcome) use a small, consistent set of labels with no case or spelling inconsistencies. Gender includes a third category, 'Prefer not to say', which should be retained as a valid response rather than treated as missing.
... A19: The dataset is fit for the Week 4/5 exploratory analysis and KPI calculation described in the Initial Analysis Document, once the two unlabeled columns are clarified and a decision is made on how to treat the small number of missing distance/waiting-time values.
